[2022-06-13 10:01:40,409] {taskinstance.py:1159} INFO - Dependencies all met for <TaskInstance: listing_4_05.get_data scheduled__2022-06-13T09:00:00+00:00 [queued]>
[2022-06-13 10:01:40,425] {taskinstance.py:1159} INFO - Dependencies all met for <TaskInstance: listing_4_05.get_data scheduled__2022-06-13T09:00:00+00:00 [queued]>
[2022-06-13 10:01:40,427] {taskinstance.py:1356} INFO - 
--------------------------------------------------------------------------------
[2022-06-13 10:01:40,429] {taskinstance.py:1357} INFO - Starting attempt 1 of 1
[2022-06-13 10:01:40,432] {taskinstance.py:1358} INFO - 
--------------------------------------------------------------------------------
[2022-06-13 10:01:40,451] {taskinstance.py:1377} INFO - Executing <Task(PythonOperator): get_data> on 2022-06-13 09:00:00+00:00
[2022-06-13 10:01:40,457] {standard_task_runner.py:52} INFO - Started process 29692 to run task
[2022-06-13 10:01:40,463] {standard_task_runner.py:79} INFO - Running: ['***', 'tasks', 'run', 'listing_4_05', 'get_data', 'scheduled__2022-06-13T09:00:00+00:00', '--job-id', '124', '--raw', '--subdir', 'DAGS_FOLDER/listing_4_5.py', '--cfg-path', '/tmp/tmp9g6wpu49', '--error-file', '/tmp/tmph9ggzuno']
[2022-06-13 10:01:40,464] {standard_task_runner.py:80} INFO - Job 124: Subtask get_data
[2022-06-13 10:01:40,544] {task_command.py:369} INFO - Running <TaskInstance: listing_4_05.get_data scheduled__2022-06-13T09:00:00+00:00 [running]> on host 48de8cc79e8d
[2022-06-13 10:01:40,633] {taskinstance.py:1571} INFO - Exporting the following env vars:
AIRFLOW_CTX_DAG_OWNER=***
AIRFLOW_CTX_DAG_ID=listing_4_05
AIRFLOW_CTX_TASK_ID=get_data
AIRFLOW_CTX_EXECUTION_DATE=2022-06-13T09:00:00+00:00
AIRFLOW_CTX_TRY_NUMBER=1
AIRFLOW_CTX_DAG_RUN_ID=scheduled__2022-06-13T09:00:00+00:00
[2022-06-13 10:01:40,636] {warnings.py:110} WARNING - /home/***/.local/lib/python3.7/site-packages/***/utils/context.py:202: AirflowContextDeprecationWarning: Accessing 'execution_date' from the template is deprecated and will be removed in a future version. Please use 'data_interval_start' or 'logical_date' instead.
  warnings.warn(_create_deprecation_warning(key, self._deprecation_replacements[key]))

[2022-06-13 10:01:40,648] {taskinstance.py:1889} ERROR - Task failed with exception
Traceback (most recent call last):
  File "/usr/local/lib/python3.7/urllib/request.py", line 1350, in do_open
    encode_chunked=req.has_header('Transfer-encoding'))
  File "/usr/local/lib/python3.7/http/client.py", line 1281, in request
    self._send_request(method, url, body, headers, encode_chunked)
  File "/usr/local/lib/python3.7/http/client.py", line 1327, in _send_request
    self.endheaders(body, encode_chunked=encode_chunked)
  File "/usr/local/lib/python3.7/http/client.py", line 1276, in endheaders
    self._send_output(message_body, encode_chunked=encode_chunked)
  File "/usr/local/lib/python3.7/http/client.py", line 1036, in _send_output
    self.send(msg)
  File "/usr/local/lib/python3.7/http/client.py", line 976, in send
    self.connect()
  File "/usr/local/lib/python3.7/http/client.py", line 1443, in connect
    super().connect()
  File "/usr/local/lib/python3.7/http/client.py", line 948, in connect
    (self.host,self.port), self.timeout, self.source_address)
  File "/usr/local/lib/python3.7/socket.py", line 707, in create_connection
    for res in getaddrinfo(host, port, 0, SOCK_STREAM):
  File "/usr/local/lib/python3.7/socket.py", line 752, in getaddrinfo
    for res in _socket.getaddrinfo(host, port, family, type, proto, flags):
socket.gaierror: [Errno -2] Name or service not known

During handling of the above exception, another exception occurred:

Traceback (most recent call last):
  File "/home/airflow/.local/lib/python3.7/site-packages/airflow/operators/python.py", line 171, in execute
    return_value = self.execute_callable()
  File "/home/airflow/.local/lib/python3.7/site-packages/airflow/operators/python.py", line 189, in execute_callable
    return self.python_callable(*self.op_args, **self.op_kwargs)
  File "/opt/airflow/dags/listing_4_5.py", line 21, in _get_data
    request.urlretrieve(url, output_path)
  File "/usr/local/lib/python3.7/urllib/request.py", line 247, in urlretrieve
    with contextlib.closing(urlopen(url, data)) as fp:
  File "/usr/local/lib/python3.7/urllib/request.py", line 222, in urlopen
    return opener.open(url, data, timeout)
  File "/usr/local/lib/python3.7/urllib/request.py", line 525, in open
    response = self._open(req, data)
  File "/usr/local/lib/python3.7/urllib/request.py", line 543, in _open
    '_open', req)
  File "/usr/local/lib/python3.7/urllib/request.py", line 503, in _call_chain
    result = func(*args)
  File "/usr/local/lib/python3.7/urllib/request.py", line 1393, in https_open
    context=self._context, check_hostname=self._check_hostname)
  File "/usr/local/lib/python3.7/urllib/request.py", line 1352, in do_open
    raise URLError(err)
urllib.error.URLError: <urlopen error [Errno -2] Name or service not known>
[2022-06-13 10:01:40,670] {taskinstance.py:1400} INFO - Marking task as FAILED. dag_id=listing_4_05, task_id=get_data, execution_date=20220613T090000, start_date=20220613T100140, end_date=20220613T100140
[2022-06-13 10:01:40,688] {standard_task_runner.py:97} ERROR - Failed to execute job 124 for task get_data (<urlopen error [Errno -2] Name or service not known>; 29692)
[2022-06-13 10:01:40,716] {local_task_job.py:156} INFO - Task exited with return code 1
[2022-06-13 10:01:40,758] {local_task_job.py:273} INFO - 0 downstream tasks scheduled from follow-on schedule check
