[2022-06-14 16:25:45,495] {taskinstance.py:1159} INFO - Dependencies all met for <TaskInstance: listing_4_05.get_data scheduled__2022-06-14T15:00:00+00:00 [queued]>
[2022-06-14 16:25:45,505] {taskinstance.py:1159} INFO - Dependencies all met for <TaskInstance: listing_4_05.get_data scheduled__2022-06-14T15:00:00+00:00 [queued]>
[2022-06-14 16:25:45,508] {taskinstance.py:1356} INFO - 
--------------------------------------------------------------------------------
[2022-06-14 16:25:45,509] {taskinstance.py:1357} INFO - Starting attempt 1 of 1
[2022-06-14 16:25:45,511] {taskinstance.py:1358} INFO - 
--------------------------------------------------------------------------------
[2022-06-14 16:25:45,523] {taskinstance.py:1377} INFO - Executing <Task(PythonOperator): get_data> on 2022-06-14 15:00:00+00:00
[2022-06-14 16:25:45,529] {standard_task_runner.py:52} INFO - Started process 74084 to run task
[2022-06-14 16:25:45,531] {standard_task_runner.py:79} INFO - Running: ['***', 'tasks', 'run', 'listing_4_05', 'get_data', 'scheduled__2022-06-14T15:00:00+00:00', '--job-id', '155', '--raw', '--subdir', 'DAGS_FOLDER/listing_4_5.py', '--cfg-path', '/tmp/tmpdo1b0rbt', '--error-file', '/tmp/tmp0pd8yhhv']
[2022-06-14 16:25:45,534] {standard_task_runner.py:80} INFO - Job 155: Subtask get_data
[2022-06-14 16:25:45,621] {task_command.py:369} INFO - Running <TaskInstance: listing_4_05.get_data scheduled__2022-06-14T15:00:00+00:00 [running]> on host 48de8cc79e8d
[2022-06-14 16:25:45,775] {taskinstance.py:1571} INFO - Exporting the following env vars:
AIRFLOW_CTX_DAG_OWNER=***
AIRFLOW_CTX_DAG_ID=listing_4_05
AIRFLOW_CTX_TASK_ID=get_data
AIRFLOW_CTX_EXECUTION_DATE=2022-06-14T15:00:00+00:00
AIRFLOW_CTX_TRY_NUMBER=1
AIRFLOW_CTX_DAG_RUN_ID=scheduled__2022-06-14T15:00:00+00:00
[2022-06-14 16:25:45,778] {warnings.py:110} WARNING - /home/***/.local/lib/python3.7/site-packages/***/utils/context.py:202: AirflowContextDeprecationWarning: Accessing 'execution_date' from the template is deprecated and will be removed in a future version. Please use 'data_interval_start' or 'logical_date' instead.
  warnings.warn(_create_deprecation_warning(key, self._deprecation_replacements[key]))

[2022-06-14 23:26:10,360] {taskinstance.py:1153} INFO - Dependencies not met for <TaskInstance: listing_4_05.get_data scheduled__2022-06-14T15:00:00+00:00 [running]>, dependency 'Task Instance Not Running' FAILED: Task is in the running state
[2022-06-14 23:26:10,366] {taskinstance.py:1153} INFO - Dependencies not met for <TaskInstance: listing_4_05.get_data scheduled__2022-06-14T15:00:00+00:00 [running]>, dependency 'Task Instance State' FAILED: Task is in the 'running' state.
[2022-06-14 23:26:10,369] {local_task_job.py:101} INFO - Task is not able to be run
[2022-06-14 23:52:17,621] {taskinstance.py:1889} ERROR - Task failed with exception
Traceback (most recent call last):
  File "/home/airflow/.local/lib/python3.7/site-packages/airflow/operators/python.py", line 171, in execute
    return_value = self.execute_callable()
  File "/home/airflow/.local/lib/python3.7/site-packages/airflow/operators/python.py", line 189, in execute_callable
    return self.python_callable(*self.op_args, **self.op_kwargs)
  File "/opt/airflow/dags/listing_4_5.py", line 21, in _get_data
    request.urlretrieve(url, output_path)
  File "/usr/local/lib/python3.7/urllib/request.py", line 247, in urlretrieve
    with contextlib.closing(urlopen(url, data)) as fp:
  File "/usr/local/lib/python3.7/urllib/request.py", line 222, in urlopen
    return opener.open(url, data, timeout)
  File "/usr/local/lib/python3.7/urllib/request.py", line 525, in open
    response = self._open(req, data)
  File "/usr/local/lib/python3.7/urllib/request.py", line 543, in _open
    '_open', req)
  File "/usr/local/lib/python3.7/urllib/request.py", line 503, in _call_chain
    result = func(*args)
  File "/usr/local/lib/python3.7/urllib/request.py", line 1393, in https_open
    context=self._context, check_hostname=self._check_hostname)
  File "/usr/local/lib/python3.7/urllib/request.py", line 1353, in do_open
    r = h.getresponse()
  File "/usr/local/lib/python3.7/http/client.py", line 1373, in getresponse
    response.begin()
  File "/usr/local/lib/python3.7/http/client.py", line 319, in begin
    version, status, reason = self._read_status()
  File "/usr/local/lib/python3.7/http/client.py", line 288, in _read_status
    raise RemoteDisconnected("Remote end closed connection without"
http.client.RemoteDisconnected: Remote end closed connection without response
[2022-06-14 23:52:17,651] {taskinstance.py:1400} INFO - Marking task as FAILED. dag_id=listing_4_05, task_id=get_data, execution_date=20220614T150000, start_date=20220614T162545, end_date=20220614T235217
[2022-06-14 23:52:17,667] {standard_task_runner.py:97} ERROR - Failed to execute job 155 for task get_data (Remote end closed connection without response; 74084)
[2022-06-14 23:52:17,714] {local_task_job.py:156} INFO - Task exited with return code 1
[2022-06-14 23:52:17,734] {local_task_job.py:273} INFO - 0 downstream tasks scheduled from follow-on schedule check
